2024-02-29 15:42:03,821 ERROR: Exception on /explore [GET] [in /Users/omidm./PycharmProjects/flask_microblog/venv/lib/python3.11/site-packages/flask/app.py:828]
Traceback (most recent call last):
  File "/Users/omidm./PycharmProjects/flask_microblog/venv/lib/python3.11/site-packages/flask/app.py", line 1463, in wsgi_app
    response = self.full_dispatch_request()
               ^^^^^^^^^^^^^^^^^^^^^^^^^^^^
  File "/Users/omidm./PycharmProjects/flask_microblog/venv/lib/python3.11/site-packages/flask/app.py", line 872, in full_dispatch_request
    rv = self.handle_user_exception(e)
         ^^^^^^^^^^^^^^^^^^^^^^^^^^^^^
  File "/Users/omidm./PycharmProjects/flask_microblog/venv/lib/python3.11/site-packages/flask/app.py", line 870, in full_dispatch_request
    rv = self.dispatch_request()
         ^^^^^^^^^^^^^^^^^^^^^^^
  File "/Users/omidm./PycharmProjects/flask_microblog/venv/lib/python3.11/site-packages/flask/app.py", line 855, in dispatch_request
    return self.ensure_sync(self.view_functions[rule.endpoint])(**view_args)  # type: ignore[no-any-return]
           ^^^^^^^^^^^^^^^^^^^^^^^^^^^^^^^^^^^^^^^^^^^^^^^^^^^^^^^^^^^^^^^^^
  File "/Users/omidm./PycharmProjects/flask_microblog/venv/lib/python3.11/site-packages/flask_login/utils.py", line 290, in decorated_view
    return current_app.ensure_sync(func)(*args, **kwargs)
           ^^^^^^^^^^^^^^^^^^^^^^^^^^^^^^^^^^^^^^^^^^^^^^
  File "/Users/omidm./PycharmProjects/flask_microblog/app/routes.py", line 143, in explore
    posts = db.sessio.scalars(query).all()
            ^^^^^^^^^
  File "/Users/omidm./PycharmProjects/flask_microblog/venv/lib/python3.11/site-packages/flask_sqlalchemy/extension.py", line 1008, in __getattr__
    raise AttributeError(name)
AttributeError: sessio
2024-02-29 15:42:18,977 ERROR: Exception on /favicon.ico [GET] [in /Users/omidm./PycharmProjects/flask_microblog/venv/lib/python3.11/site-packages/flask/app.py:828]
Traceback (most recent call last):
  File "/Users/omidm./PycharmProjects/flask_microblog/venv/lib/python3.11/site-packages/flask/app.py", line 1463, in wsgi_app
    response = self.full_dispatch_request()
               ^^^^^^^^^^^^^^^^^^^^^^^^^^^^
  File "/Users/omidm./PycharmProjects/flask_microblog/venv/lib/python3.11/site-packages/flask/app.py", line 873, in full_dispatch_request
    return self.finalize_request(rv)
           ^^^^^^^^^^^^^^^^^^^^^^^^^
  File "/Users/omidm./PycharmProjects/flask_microblog/venv/lib/python3.11/site-packages/flask/app.py", line 892, in finalize_request
    response = self.make_response(rv)
               ^^^^^^^^^^^^^^^^^^^^^^
  File "/Users/omidm./PycharmProjects/flask_microblog/venv/lib/python3.11/site-packages/flask/app.py", line 1164, in make_response
    raise TypeError(
TypeError: The view function for None did not return a valid response. The function either returned None or ended without a return statement.
2024-02-29 15:42:25,777 ERROR: Exception on /explore [GET] [in /Users/omidm./PycharmProjects/flask_microblog/venv/lib/python3.11/site-packages/flask/app.py:828]
Traceback (most recent call last):
  File "/Users/omidm./PycharmProjects/flask_microblog/venv/lib/python3.11/site-packages/flask/app.py", line 1463, in wsgi_app
    response = self.full_dispatch_request()
               ^^^^^^^^^^^^^^^^^^^^^^^^^^^^
  File "/Users/omidm./PycharmProjects/flask_microblog/venv/lib/python3.11/site-packages/flask/app.py", line 872, in full_dispatch_request
    rv = self.handle_user_exception(e)
         ^^^^^^^^^^^^^^^^^^^^^^^^^^^^^
  File "/Users/omidm./PycharmProjects/flask_microblog/venv/lib/python3.11/site-packages/flask/app.py", line 870, in full_dispatch_request
    rv = self.dispatch_request()
         ^^^^^^^^^^^^^^^^^^^^^^^
  File "/Users/omidm./PycharmProjects/flask_microblog/venv/lib/python3.11/site-packages/flask/app.py", line 855, in dispatch_request
    return self.ensure_sync(self.view_functions[rule.endpoint])(**view_args)  # type: ignore[no-any-return]
           ^^^^^^^^^^^^^^^^^^^^^^^^^^^^^^^^^^^^^^^^^^^^^^^^^^^^^^^^^^^^^^^^^
  File "/Users/omidm./PycharmProjects/flask_microblog/venv/lib/python3.11/site-packages/flask_login/utils.py", line 290, in decorated_view
    return current_app.ensure_sync(func)(*args, **kwargs)
           ^^^^^^^^^^^^^^^^^^^^^^^^^^^^^^^^^^^^^^^^^^^^^^
  File "/Users/omidm./PycharmProjects/flask_microblog/app/routes.py", line 143, in explore
    posts = db.sessio.scalars(query).all()
            ^^^^^^^^^
  File "/Users/omidm./PycharmProjects/flask_microblog/venv/lib/python3.11/site-packages/flask_sqlalchemy/extension.py", line 1008, in __getattr__
    raise AttributeError(name)
AttributeError: sessio
2024-02-29 20:21:00,150 INFO: Microblog startup [in /Users/omidm./PycharmProjects/flask_microblog/app/__init__.py:44]
2024-02-29 20:21:52,861 INFO: Microblog startup [in /Users/omidm./PycharmProjects/flask_microblog/app/__init__.py:44]
2024-02-29 20:21:54,304 ERROR: Exception on /favicon.ico [GET] [in /Users/omidm./PycharmProjects/flask_microblog/venv/lib/python3.11/site-packages/flask/app.py:828]
Traceback (most recent call last):
  File "/Users/omidm./PycharmProjects/flask_microblog/venv/lib/python3.11/site-packages/flask/app.py", line 1463, in wsgi_app
    response = self.full_dispatch_request()
               ^^^^^^^^^^^^^^^^^^^^^^^^^^^^
  File "/Users/omidm./PycharmProjects/flask_microblog/venv/lib/python3.11/site-packages/flask/app.py", line 873, in full_dispatch_request
    return self.finalize_request(rv)
           ^^^^^^^^^^^^^^^^^^^^^^^^^
  File "/Users/omidm./PycharmProjects/flask_microblog/venv/lib/python3.11/site-packages/flask/app.py", line 892, in finalize_request
    response = self.make_response(rv)
               ^^^^^^^^^^^^^^^^^^^^^^
  File "/Users/omidm./PycharmProjects/flask_microblog/venv/lib/python3.11/site-packages/flask/app.py", line 1164, in make_response
    raise TypeError(
TypeError: The view function for None did not return a valid response. The function either returned None or ended without a return statement.
2024-02-29 20:22:01,526 ERROR: Exception on /favicon.ico [GET] [in /Users/omidm./PycharmProjects/flask_microblog/venv/lib/python3.11/site-packages/flask/app.py:828]
Traceback (most recent call last):
  File "/Users/omidm./PycharmProjects/flask_microblog/venv/lib/python3.11/site-packages/flask/app.py", line 1463, in wsgi_app
    response = self.full_dispatch_request()
               ^^^^^^^^^^^^^^^^^^^^^^^^^^^^
  File "/Users/omidm./PycharmProjects/flask_microblog/venv/lib/python3.11/site-packages/flask/app.py", line 873, in full_dispatch_request
    return self.finalize_request(rv)
           ^^^^^^^^^^^^^^^^^^^^^^^^^
  File "/Users/omidm./PycharmProjects/flask_microblog/venv/lib/python3.11/site-packages/flask/app.py", line 892, in finalize_request
    response = self.make_response(rv)
               ^^^^^^^^^^^^^^^^^^^^^^
  File "/Users/omidm./PycharmProjects/flask_microblog/venv/lib/python3.11/site-packages/flask/app.py", line 1164, in make_response
    raise TypeError(
TypeError: The view function for None did not return a valid response. The function either returned None or ended without a return statement.
